{
 "cells": [
  {
   "cell_type": "code",
   "execution_count": 12,
   "metadata": {},
   "outputs": [
    {
     "name": "stdout",
     "output_type": "stream",
     "text": [
      "ERROR! Session/line number was not unique in database. History logging moved to new session 1054\n",
      "Requirement already satisfied: torchvision==0.2.2 in /opt/anaconda3/lib/python3.7/site-packages (0.2.2)\n",
      "Requirement already satisfied: numpy in /opt/anaconda3/lib/python3.7/site-packages (from torchvision==0.2.2) (1.19.4)\n",
      "Requirement already satisfied: pillow>=4.1.1 in /opt/anaconda3/lib/python3.7/site-packages (from torchvision==0.2.2) (9.0.1)\n",
      "Requirement already satisfied: six in /opt/anaconda3/lib/python3.7/site-packages (from torchvision==0.2.2) (1.16.0)\n",
      "Requirement already satisfied: tqdm==4.19.9 in /opt/anaconda3/lib/python3.7/site-packages (from torchvision==0.2.2) (4.19.9)\n",
      "Requirement already satisfied: torch in /opt/anaconda3/lib/python3.7/site-packages (from torchvision==0.2.2) (1.0.0)\n",
      "\u001b[33mWARNING: Error parsing requirements for google-pasta: [Errno 2] No such file or directory: '/opt/anaconda3/lib/python3.7/site-packages/google_pasta-0.2.0.dist-info/METADATA'\u001b[0m\n",
      "\u001b[33mWARNING: Error parsing requirements for absl-py: [Errno 2] No such file or directory: '/opt/anaconda3/lib/python3.7/site-packages/absl_py-0.11.0.dist-info/METADATA'\u001b[0m\n"
     ]
    }
   ],
   "source": [
    "!pip3 install torchvision==0.2.2"
   ]
  },
  {
   "cell_type": "code",
   "execution_count": 13,
   "metadata": {},
   "outputs": [
    {
     "name": "stdout",
     "output_type": "stream",
     "text": [
      "Requirement already satisfied: torch==1.0.0 in /opt/anaconda3/lib/python3.7/site-packages (1.0.0)\n",
      "\u001b[33mWARNING: Error parsing requirements for google-pasta: [Errno 2] No such file or directory: '/opt/anaconda3/lib/python3.7/site-packages/google_pasta-0.2.0.dist-info/METADATA'\u001b[0m\n",
      "\u001b[33mWARNING: Error parsing requirements for absl-py: [Errno 2] No such file or directory: '/opt/anaconda3/lib/python3.7/site-packages/absl_py-0.11.0.dist-info/METADATA'\u001b[0m\n"
     ]
    }
   ],
   "source": [
    "!pip3 install torch==1.0.0"
   ]
  },
  {
   "cell_type": "code",
   "execution_count": 14,
   "metadata": {},
   "outputs": [
    {
     "name": "stdout",
     "output_type": "stream",
     "text": [
      "Requirement already satisfied: pandas in /opt/anaconda3/lib/python3.7/site-packages (1.3.5)\n",
      "Requirement already satisfied: pytz>=2017.3 in /opt/anaconda3/lib/python3.7/site-packages (from pandas) (2021.3)\n",
      "Requirement already satisfied: numpy>=1.17.3 in /opt/anaconda3/lib/python3.7/site-packages (from pandas) (1.19.4)\n",
      "Requirement already satisfied: python-dateutil>=2.7.3 in /opt/anaconda3/lib/python3.7/site-packages (from pandas) (2.8.2)\n",
      "Requirement already satisfied: six>=1.5 in /opt/anaconda3/lib/python3.7/site-packages (from python-dateutil>=2.7.3->pandas) (1.16.0)\n",
      "\u001b[33mWARNING: Error parsing requirements for google-pasta: [Errno 2] No such file or directory: '/opt/anaconda3/lib/python3.7/site-packages/google_pasta-0.2.0.dist-info/METADATA'\u001b[0m\n",
      "\u001b[33mWARNING: Error parsing requirements for absl-py: [Errno 2] No such file or directory: '/opt/anaconda3/lib/python3.7/site-packages/absl_py-0.11.0.dist-info/METADATA'\u001b[0m\n"
     ]
    }
   ],
   "source": [
    "!pip3 install --upgrade pandas"
   ]
  },
  {
   "cell_type": "code",
   "execution_count": null,
   "metadata": {},
   "outputs": [],
   "source": []
  },
  {
   "cell_type": "code",
   "execution_count": null,
   "metadata": {},
   "outputs": [
    {
     "name": "stderr",
     "output_type": "stream",
     "text": [
      "Using TensorFlow backend.\n",
      "ERROR:root:Internal Python error in the inspect module.\n",
      "Below is the traceback from this internal error.\n",
      "\n",
      "ERROR:root:Internal Python error in the inspect module.\n",
      "Below is the traceback from this internal error.\n",
      "\n",
      "ERROR:root:Internal Python error in the inspect module.\n",
      "Below is the traceback from this internal error.\n",
      "\n"
     ]
    },
    {
     "name": "stdout",
     "output_type": "stream",
     "text": [
      "Traceback (most recent call last):\n",
      "  File \"/opt/anaconda3/lib/python3.7/site-packages/IPython/core/interactiveshell.py\", line 3418, in run_code\n",
      "  File \"<ipython-input-12-226f39387ca0>\", line 13, in <module>\n",
      "    from keras.layers import Flatten\n",
      "  File \"/opt/anaconda3/lib/python3.7/site-packages/keras/__init__.py\", line 3, in <module>\n",
      "    from . import utils\n",
      "  File \"/opt/anaconda3/lib/python3.7/site-packages/keras/utils/__init__.py\", line 6, in <module>\n",
      "    from . import conv_utils\n",
      "  File \"/opt/anaconda3/lib/python3.7/site-packages/keras/utils/conv_utils.py\", line 9, in <module>\n",
      "    from .. import backend as K\n",
      "  File \"/opt/anaconda3/lib/python3.7/site-packages/keras/backend/__init__.py\", line 1, in <module>\n",
      "    from .load_backend import epsilon\n",
      "  File \"/opt/anaconda3/lib/python3.7/site-packages/keras/backend/load_backend.py\", line 90, in <module>\n",
      "    from .tensorflow_backend import *\n",
      "  File \"/opt/anaconda3/lib/python3.7/site-packages/keras/backend/tensorflow_backend.py\", line 6, in <module>\n",
      "    from tensorflow.python.eager import context\n",
      "ImportError: cannot import name 'context' from 'tensorflow.python.eager' (/opt/anaconda3/lib/python3.7/site-packages/tensorflow_core/python/eager/__init__.py)\n",
      "\n",
      "During handling of the above exception, another exception occurred:\n",
      "\n",
      "Traceback (most recent call last):\n",
      "  File \"/opt/anaconda3/lib/python3.7/site-packages/IPython/core/interactiveshell.py\", line 2045, in showtraceback\n",
      "    should be used throughout the code for presenting user tracebacks,\n",
      "AttributeError: 'ImportError' object has no attribute '_render_traceback_'\n",
      "\n",
      "During handling of the above exception, another exception occurred:\n",
      "\n",
      "Traceback (most recent call last):\n",
      "  File \"/opt/anaconda3/lib/python3.7/site-packages/IPython/core/ultratb.py\", line 1170, in get_records\n",
      "  File \"/opt/anaconda3/lib/python3.7/site-packages/IPython/core/ultratb.py\", line 316, in wrapped\n",
      "  File \"/opt/anaconda3/lib/python3.7/site-packages/IPython/core/ultratb.py\", line 350, in _fixed_getinnerframes\n",
      "  File \"/opt/anaconda3/lib/python3.7/inspect.py\", line 1502, in getinnerframes\n",
      "    frameinfo = (tb.tb_frame,) + getframeinfo(tb, context)\n",
      "  File \"/opt/anaconda3/lib/python3.7/inspect.py\", line 1460, in getframeinfo\n",
      "    filename = getsourcefile(frame) or getfile(frame)\n",
      "  File \"/opt/anaconda3/lib/python3.7/inspect.py\", line 696, in getsourcefile\n",
      "    if getattr(getmodule(object, filename), '__loader__', None) is not None:\n",
      "  File \"/opt/anaconda3/lib/python3.7/inspect.py\", line 733, in getmodule\n",
      "    if ismodule(module) and hasattr(module, '__file__'):\n",
      "  File \"/opt/anaconda3/lib/python3.7/site-packages/tensorflow/__init__.py\", line 50, in __getattr__\n",
      "  File \"/opt/anaconda3/lib/python3.7/site-packages/tensorflow/__init__.py\", line 44, in _load\n",
      "  File \"/opt/anaconda3/lib/python3.7/importlib/__init__.py\", line 127, in import_module\n",
      "    return _bootstrap._gcd_import(name[level:], package, level)\n",
      "  File \"<frozen importlib._bootstrap>\", line 1006, in _gcd_import\n",
      "  File \"<frozen importlib._bootstrap>\", line 983, in _find_and_load\n",
      "  File \"<frozen importlib._bootstrap>\", line 953, in _find_and_load_unlocked\n",
      "  File \"<frozen importlib._bootstrap>\", line 219, in _call_with_frames_removed\n",
      "  File \"<frozen importlib._bootstrap>\", line 1006, in _gcd_import\n",
      "  File \"<frozen importlib._bootstrap>\", line 983, in _find_and_load\n",
      "  File \"<frozen importlib._bootstrap>\", line 965, in _find_and_load_unlocked\n",
      "ModuleNotFoundError: No module named 'tensorflow_core'\n",
      "Traceback (most recent call last):\n",
      "  File \"/opt/anaconda3/lib/python3.7/site-packages/IPython/core/interactiveshell.py\", line 3418, in run_code\n",
      "  File \"<ipython-input-12-226f39387ca0>\", line 13, in <module>\n",
      "    from keras.layers import Flatten\n",
      "  File \"/opt/anaconda3/lib/python3.7/site-packages/keras/__init__.py\", line 3, in <module>\n",
      "    from . import utils\n",
      "  File \"/opt/anaconda3/lib/python3.7/site-packages/keras/utils/__init__.py\", line 6, in <module>\n",
      "    from . import conv_utils\n",
      "  File \"/opt/anaconda3/lib/python3.7/site-packages/keras/utils/conv_utils.py\", line 9, in <module>\n",
      "    from .. import backend as K\n",
      "  File \"/opt/anaconda3/lib/python3.7/site-packages/keras/backend/__init__.py\", line 1, in <module>\n",
      "    from .load_backend import epsilon\n",
      "  File \"/opt/anaconda3/lib/python3.7/site-packages/keras/backend/load_backend.py\", line 90, in <module>\n",
      "    from .tensorflow_backend import *\n",
      "  File \"/opt/anaconda3/lib/python3.7/site-packages/keras/backend/tensorflow_backend.py\", line 6, in <module>\n",
      "    from tensorflow.python.eager import context\n",
      "ImportError: cannot import name 'context' from 'tensorflow.python.eager' (/opt/anaconda3/lib/python3.7/site-packages/tensorflow_core/python/eager/__init__.py)\n",
      "\n",
      "During handling of the above exception, another exception occurred:\n",
      "\n",
      "Traceback (most recent call last):\n",
      "  File \"/opt/anaconda3/lib/python3.7/site-packages/IPython/core/interactiveshell.py\", line 2045, in showtraceback\n",
      "    should be used throughout the code for presenting user tracebacks,\n",
      "AttributeError: 'ImportError' object has no attribute '_render_traceback_'\n",
      "\n",
      "During handling of the above exception, another exception occurred:\n",
      "\n",
      "Traceback (most recent call last):\n",
      "  File \"/opt/anaconda3/lib/python3.7/site-packages/IPython/core/interactiveshell.py\", line 3338, in run_ast_nodes\n",
      "  File \"/opt/anaconda3/lib/python3.7/site-packages/IPython/core/interactiveshell.py\", line 3435, in run_code\n",
      "    \"\"\"\n",
      "  File \"/opt/anaconda3/lib/python3.7/site-packages/IPython/core/interactiveshell.py\", line 2048, in showtraceback\n",
      "    A specific showsyntaxerror() also exists, but this method can take\n",
      "  File \"/opt/anaconda3/lib/python3.7/site-packages/IPython/core/ultratb.py\", line 1437, in structured_traceback\n",
      "    # getattr raising\n",
      "  File \"/opt/anaconda3/lib/python3.7/site-packages/IPython/core/ultratb.py\", line 1337, in structured_traceback\n",
      "  File \"/opt/anaconda3/lib/python3.7/site-packages/IPython/core/ultratb.py\", line 1194, in structured_traceback\n",
      "    self.tb = self.tb.tb_next\n",
      "  File \"/opt/anaconda3/lib/python3.7/site-packages/IPython/core/ultratb.py\", line 1151, in format_exception_as_a_whole\n",
      "    evalue = None\n",
      "  File \"/opt/anaconda3/lib/python3.7/site-packages/IPython/core/ultratb.py\", line 451, in find_recursion\n",
      "    - Any object with 'write' and 'flush' attributes.\n",
      "TypeError: object of type 'NoneType' has no len()\n",
      "\n",
      "During handling of the above exception, another exception occurred:\n",
      "\n",
      "Traceback (most recent call last):\n",
      "  File \"/opt/anaconda3/lib/python3.7/site-packages/IPython/core/interactiveshell.py\", line 2045, in showtraceback\n",
      "    should be used throughout the code for presenting user tracebacks,\n",
      "AttributeError: 'TypeError' object has no attribute '_render_traceback_'\n",
      "\n",
      "During handling of the above exception, another exception occurred:\n",
      "\n",
      "Traceback (most recent call last):\n",
      "  File \"/opt/anaconda3/lib/python3.7/site-packages/IPython/core/ultratb.py\", line 1170, in get_records\n",
      "  File \"/opt/anaconda3/lib/python3.7/site-packages/IPython/core/ultratb.py\", line 316, in wrapped\n",
      "  File \"/opt/anaconda3/lib/python3.7/site-packages/IPython/core/ultratb.py\", line 350, in _fixed_getinnerframes\n",
      "  File \"/opt/anaconda3/lib/python3.7/inspect.py\", line 1502, in getinnerframes\n",
      "    frameinfo = (tb.tb_frame,) + getframeinfo(tb, context)\n",
      "  File \"/opt/anaconda3/lib/python3.7/inspect.py\", line 1460, in getframeinfo\n",
      "    filename = getsourcefile(frame) or getfile(frame)\n",
      "  File \"/opt/anaconda3/lib/python3.7/inspect.py\", line 696, in getsourcefile\n",
      "    if getattr(getmodule(object, filename), '__loader__', None) is not None:\n",
      "  File \"/opt/anaconda3/lib/python3.7/inspect.py\", line 733, in getmodule\n",
      "    if ismodule(module) and hasattr(module, '__file__'):\n",
      "  File \"/opt/anaconda3/lib/python3.7/site-packages/tensorflow/__init__.py\", line 50, in __getattr__\n",
      "  File \"/opt/anaconda3/lib/python3.7/site-packages/tensorflow/__init__.py\", line 44, in _load\n",
      "  File \"/opt/anaconda3/lib/python3.7/importlib/__init__.py\", line 127, in import_module\n",
      "    return _bootstrap._gcd_import(name[level:], package, level)\n",
      "  File \"<frozen importlib._bootstrap>\", line 1006, in _gcd_import\n",
      "  File \"<frozen importlib._bootstrap>\", line 983, in _find_and_load\n",
      "  File \"<frozen importlib._bootstrap>\", line 953, in _find_and_load_unlocked\n",
      "  File \"<frozen importlib._bootstrap>\", line 219, in _call_with_frames_removed\n",
      "  File \"<frozen importlib._bootstrap>\", line 1006, in _gcd_import\n",
      "  File \"<frozen importlib._bootstrap>\", line 983, in _find_and_load\n",
      "  File \"<frozen importlib._bootstrap>\", line 965, in _find_and_load_unlocked\n",
      "ModuleNotFoundError: No module named 'tensorflow_core'\n",
      "Traceback (most recent call last):\n",
      "  File \"/opt/anaconda3/lib/python3.7/site-packages/IPython/core/interactiveshell.py\", line 3418, in run_code\n",
      "  File \"<ipython-input-12-226f39387ca0>\", line 13, in <module>\n",
      "    from keras.layers import Flatten\n",
      "  File \"/opt/anaconda3/lib/python3.7/site-packages/keras/__init__.py\", line 3, in <module>\n",
      "    from . import utils\n",
      "  File \"/opt/anaconda3/lib/python3.7/site-packages/keras/utils/__init__.py\", line 6, in <module>\n",
      "    from . import conv_utils\n",
      "  File \"/opt/anaconda3/lib/python3.7/site-packages/keras/utils/conv_utils.py\", line 9, in <module>\n",
      "    from .. import backend as K\n",
      "  File \"/opt/anaconda3/lib/python3.7/site-packages/keras/backend/__init__.py\", line 1, in <module>\n",
      "    from .load_backend import epsilon\n",
      "  File \"/opt/anaconda3/lib/python3.7/site-packages/keras/backend/load_backend.py\", line 90, in <module>\n",
      "    from .tensorflow_backend import *\n",
      "  File \"/opt/anaconda3/lib/python3.7/site-packages/keras/backend/tensorflow_backend.py\", line 6, in <module>\n",
      "    from tensorflow.python.eager import context\n",
      "ImportError: cannot import name 'context' from 'tensorflow.python.eager' (/opt/anaconda3/lib/python3.7/site-packages/tensorflow_core/python/eager/__init__.py)\n",
      "\n",
      "During handling of the above exception, another exception occurred:\n",
      "\n",
      "Traceback (most recent call last):\n",
      "  File \"/opt/anaconda3/lib/python3.7/site-packages/IPython/core/interactiveshell.py\", line 2045, in showtraceback\n",
      "    should be used throughout the code for presenting user tracebacks,\n",
      "AttributeError: 'ImportError' object has no attribute '_render_traceback_'\n",
      "\n",
      "During handling of the above exception, another exception occurred:\n",
      "\n",
      "Traceback (most recent call last):\n",
      "  File \"/opt/anaconda3/lib/python3.7/site-packages/IPython/core/interactiveshell.py\", line 3338, in run_ast_nodes\n",
      "  File \"/opt/anaconda3/lib/python3.7/site-packages/IPython/core/interactiveshell.py\", line 3435, in run_code\n",
      "    \"\"\"\n",
      "  File \"/opt/anaconda3/lib/python3.7/site-packages/IPython/core/interactiveshell.py\", line 2048, in showtraceback\n",
      "    A specific showsyntaxerror() also exists, but this method can take\n",
      "  File \"/opt/anaconda3/lib/python3.7/site-packages/IPython/core/ultratb.py\", line 1437, in structured_traceback\n",
      "    # getattr raising\n",
      "  File \"/opt/anaconda3/lib/python3.7/site-packages/IPython/core/ultratb.py\", line 1337, in structured_traceback\n",
      "  File \"/opt/anaconda3/lib/python3.7/site-packages/IPython/core/ultratb.py\", line 1194, in structured_traceback\n",
      "    self.tb = self.tb.tb_next\n",
      "  File \"/opt/anaconda3/lib/python3.7/site-packages/IPython/core/ultratb.py\", line 1151, in format_exception_as_a_whole\n",
      "    evalue = None\n",
      "  File \"/opt/anaconda3/lib/python3.7/site-packages/IPython/core/ultratb.py\", line 451, in find_recursion\n",
      "    - Any object with 'write' and 'flush' attributes.\n",
      "TypeError: object of type 'NoneType' has no len()\n",
      "\n",
      "During handling of the above exception, another exception occurred:\n",
      "\n",
      "Traceback (most recent call last):\n",
      "  File \"/opt/anaconda3/lib/python3.7/site-packages/IPython/core/interactiveshell.py\", line 2045, in showtraceback\n",
      "    should be used throughout the code for presenting user tracebacks,\n",
      "AttributeError: 'TypeError' object has no attribute '_render_traceback_'\n",
      "\n",
      "During handling of the above exception, another exception occurred:\n",
      "\n",
      "Traceback (most recent call last):\n",
      "  File \"/opt/anaconda3/lib/python3.7/site-packages/IPython/core/interactiveshell.py\", line 2923, in _run_cell\n",
      "    \"\"\"Internal method to run a complete IPython cell.\"\"\"\n",
      "  File \"/opt/anaconda3/lib/python3.7/site-packages/IPython/core/async_helpers.py\", line 68, in _pseudo_sync_runner\n",
      "    def _pseudo_sync_runner(coro):\n",
      "  File \"/opt/anaconda3/lib/python3.7/site-packages/IPython/core/interactiveshell.py\", line 3147, in run_cell_async\n",
      "    #    - Let it go through the AST transformers, and graft\n",
      "  File \"/opt/anaconda3/lib/python3.7/site-packages/IPython/core/interactiveshell.py\", line 3357, in run_ast_nodes\n",
      "    else:\n",
      "  File \"/opt/anaconda3/lib/python3.7/site-packages/IPython/core/interactiveshell.py\", line 2048, in showtraceback\n",
      "    A specific showsyntaxerror() also exists, but this method can take\n",
      "  File \"/opt/anaconda3/lib/python3.7/site-packages/IPython/core/ultratb.py\", line 1437, in structured_traceback\n",
      "    # getattr raising\n",
      "  File \"/opt/anaconda3/lib/python3.7/site-packages/IPython/core/ultratb.py\", line 1337, in structured_traceback\n",
      "  File \"/opt/anaconda3/lib/python3.7/site-packages/IPython/core/ultratb.py\", line 1212, in structured_traceback\n",
      "    # Changed so an instance can just be called as VerboseTB_inst() and print\n",
      "  File \"/opt/anaconda3/lib/python3.7/site-packages/IPython/core/ultratb.py\", line 1151, in format_exception_as_a_whole\n",
      "    evalue = None\n",
      "  File \"/opt/anaconda3/lib/python3.7/site-packages/IPython/core/ultratb.py\", line 451, in find_recursion\n",
      "    - Any object with 'write' and 'flush' attributes.\n",
      "TypeError: object of type 'NoneType' has no len()\n",
      "\n",
      "During handling of the above exception, another exception occurred:\n",
      "\n",
      "Traceback (most recent call last):\n",
      "  File \"/opt/anaconda3/lib/python3.7/site-packages/IPython/core/interactiveshell.py\", line 2045, in showtraceback\n",
      "    should be used throughout the code for presenting user tracebacks,\n",
      "AttributeError: 'TypeError' object has no attribute '_render_traceback_'\n",
      "\n",
      "During handling of the above exception, another exception occurred:\n",
      "\n",
      "Traceback (most recent call last):\n",
      "  File \"/opt/anaconda3/lib/python3.7/site-packages/IPython/core/ultratb.py\", line 1170, in get_records\n",
      "  File \"/opt/anaconda3/lib/python3.7/site-packages/IPython/core/ultratb.py\", line 316, in wrapped\n",
      "  File \"/opt/anaconda3/lib/python3.7/site-packages/IPython/core/ultratb.py\", line 350, in _fixed_getinnerframes\n",
      "  File \"/opt/anaconda3/lib/python3.7/inspect.py\", line 1502, in getinnerframes\n",
      "    frameinfo = (tb.tb_frame,) + getframeinfo(tb, context)\n",
      "  File \"/opt/anaconda3/lib/python3.7/inspect.py\", line 1460, in getframeinfo\n",
      "    filename = getsourcefile(frame) or getfile(frame)\n",
      "  File \"/opt/anaconda3/lib/python3.7/inspect.py\", line 696, in getsourcefile\n",
      "    if getattr(getmodule(object, filename), '__loader__', None) is not None:\n",
      "  File \"/opt/anaconda3/lib/python3.7/inspect.py\", line 733, in getmodule\n",
      "    if ismodule(module) and hasattr(module, '__file__'):\n",
      "  File \"/opt/anaconda3/lib/python3.7/site-packages/tensorflow/__init__.py\", line 50, in __getattr__\n",
      "  File \"/opt/anaconda3/lib/python3.7/site-packages/tensorflow/__init__.py\", line 44, in _load\n",
      "  File \"/opt/anaconda3/lib/python3.7/importlib/__init__.py\", line 127, in import_module\n",
      "    return _bootstrap._gcd_import(name[level:], package, level)\n",
      "  File \"<frozen importlib._bootstrap>\", line 1006, in _gcd_import\n",
      "  File \"<frozen importlib._bootstrap>\", line 983, in _find_and_load\n",
      "  File \"<frozen importlib._bootstrap>\", line 953, in _find_and_load_unlocked\n",
      "  File \"<frozen importlib._bootstrap>\", line 219, in _call_with_frames_removed\n",
      "  File \"<frozen importlib._bootstrap>\", line 1006, in _gcd_import\n",
      "  File \"<frozen importlib._bootstrap>\", line 983, in _find_and_load\n",
      "  File \"<frozen importlib._bootstrap>\", line 965, in _find_and_load_unlocked\n",
      "ModuleNotFoundError: No module named 'tensorflow_core'\n"
     ]
    }
   ],
   "source": [
    "import cv2\n",
    "import time\n",
    "from faceclass import face_detection\n",
    "from camera import Camera\n",
    "import os\n",
    "import glob\n",
    "from torchvision.transforms import transforms\n",
    "from torch.utils.data import DataLoader\n",
    "import torchvision\n",
    "import torch\n",
    "from torch.optim import Adam, SGD\n",
    "from torch.nn import Linear, ReLU, Sequential, MaxPool2d, Conv2d, Module, Softmax, CrossEntropyLoss"
   ]
  },
  {
   "cell_type": "code",
   "execution_count": null,
   "metadata": {},
   "outputs": [],
   "source": []
  },
  {
   "cell_type": "code",
   "execution_count": null,
   "metadata": {},
   "outputs": [],
   "source": [
    "#get the data path\n",
    "cwd = os.getcwd()\n",
    "dataset_path = os.path.join(cwd,\"dataset\") "
   ]
  },
  {
   "cell_type": "code",
   "execution_count": null,
   "metadata": {},
   "outputs": [],
   "source": [
    "#transform the data\n",
    "transformer = transforms.Compose([\n",
    "\ttransforms.Resize((128,128)),\n",
    "\ttransforms.RandomHorizontalFlip(),\n",
    "\ttransforms.ToTensor(),\n",
    "\ttransforms.Normalize([0.5,0.5,0.5],[0.5,0.5,0.5]) #(0-255)\n",
    "])"
   ]
  },
  {
   "cell_type": "code",
   "execution_count": null,
   "metadata": {},
   "outputs": [],
   "source": [
    "#load the data with the above transformation\n",
    "train_loader = DataLoader(torchvision.datasets.ImageFolder(dataset_path, transform = transformer),batch_size = 16,shuffle = True)"
   ]
  },
  {
   "cell_type": "code",
   "execution_count": null,
   "metadata": {},
   "outputs": [],
   "source": [
    "#create the model class\n",
    "class CNN(Module):\n",
    "    def __init__(self,num_classes = 2):\n",
    "        super(CNN, self).__init__()\n",
    "        \n",
    "        #output size of conv2d layer is ((w-f+2P)/s)+1\n",
    "\n",
    "        #input size if (16,3,128,128)\n",
    "        \n",
    "        self.cnn_layers = Sequential(\n",
    "                Conv2d(in_channels = 3 , out_channels =32 ,kernel_size=5),\n",
    "            #output = (16,32,128,128)\n",
    "                ReLU(),\n",
    "                Conv2d(in_channels = 32, out_channels = 32, kernel_size = 5),\n",
    "            #output = (16,32,128,128)\n",
    "                ReLU(),\n",
    "                MaxPool2d(kernel_size = 2, stride=2))\n",
    "        #output = (16,32,64,64)\n",
    "        self.fc1 = Linear(32*60*60, num_classes)\n",
    " \n",
    "    def forward(self,x):\n",
    "        out = self.cnn_layers(x)\n",
    "        out = torch.flatten(out, 1)\n",
    "        out = self.fc1(out)\n",
    "        return out\n"
   ]
  },
  {
   "cell_type": "code",
   "execution_count": null,
   "metadata": {},
   "outputs": [],
   "source": [
    "#create the model\n",
    "model = CNN()\n",
    "#output = model(images)\n",
    "\n",
    "#optimizer and loss functions\n",
    "optimizer = Adam(model.parameters(), lr = 0.001, weight_decay = 0.0001 )\n",
    "loss_function = CrossEntropyLoss()"
   ]
  },
  {
   "cell_type": "code",
   "execution_count": null,
   "metadata": {},
   "outputs": [],
   "source": [
    "\n",
    "num_epochs = 10\n",
    "train_count = len(glob.glob(dataset_path + \"/**/*.jpg\" ))\n",
    "\n",
    "#train model\n",
    "for epoch in range(num_epochs):\n",
    "\n",
    "    train_accuracy = 0.0\n",
    "    model.train()\n",
    "    for i, (images,labels) in enumerate(train_loader):\n",
    "\n",
    "        optimizer.zero_grad()\n",
    "        outputs = model(images)\n",
    "        #calculate the loss and back propogate\n",
    "        loss = loss_function(outputs,labels)\n",
    "        loss.backward()\n",
    "        optimizer.step()\n",
    "\n",
    "        _,prediction = torch.max(outputs.data,1)\n",
    "        train_accuracy += int(torch.sum(prediction==labels.data))\n",
    "\n",
    "    train_accuracy = train_accuracy/train_count\n",
    "    print(\"EPOCH: \" + str(epoch) + \"accuracy:  \", train_accuracy)\n",
    "    \n",
    "    model.eval()"
   ]
  },
  {
   "cell_type": "code",
   "execution_count": null,
   "metadata": {},
   "outputs": [],
   "source": []
  },
  {
   "cell_type": "code",
   "execution_count": null,
   "metadata": {},
   "outputs": [],
   "source": []
  }
 ],
 "metadata": {
  "kernelspec": {
   "display_name": "Python 3 (ipykernel)",
   "language": "python",
   "name": "python3"
  },
  "language_info": {
   "codemirror_mode": {
    "name": "ipython",
    "version": 3
   },
   "file_extension": ".py",
   "mimetype": "text/x-python",
   "name": "python",
   "nbconvert_exporter": "python",
   "pygments_lexer": "ipython3",
   "version": "3.7.4"
  }
 },
 "nbformat": 4,
 "nbformat_minor": 4
}
